<?xml version="1.0" ?>
<!-- =================================================================================== -->
<!-- |    This document was autogenerated by xacro from /home/user/projects/shadow_robot/base/src/fh_common/fh_description/robots/hand_h_v2_no_wrist.xacro | -->
<!-- |    EDITING THIS FILE BY HAND IS NOT RECOMMENDED                                 | -->
<!-- =================================================================================== -->
<robot name="hand_H_v2" xmlns:xacro="http://ros.org/wiki/xacro">
  <mujoco> 
   <compiler angle="radian" inertiafromgeom="true" texturedir="textures/" meshdir="meshes/visual/"/><option timestep="2e-3" iterations="10" tolerance="1e-10" impratio="20"/><size njmax="600" nconmax="150" nstack="300000"/>
   <keyframe>
        <key time="0" qpos="0 0 0 0 0 0 0 0 0 0 0 0 0 0 0" />
    </keyframe>
  </mujoco>
  <link name="world"/>
  <material name="Blue">
    <color rgba="0.0 0.0 0.8 1.0"/>
  </material>
  <material name="Green">
    <color rgba="0.0 0.8 0.0 1.0"/>
  </material>
  <material name="BiotacGreen">
    <color rgba="0.31 0.85 0.42 1.0"/>
  </material>
  <material name="Grey">
    <color rgba="0.2 0.2 0.2 1.0"/>
  </material>
  <material name="LightGrey">
    <color rgba="0.6 0.6 0.6 1.0"/>
  </material>
  <material name="Red">
    <color rgba="0.8 0.0 0.0 1.0"/>
  </material>
  <material name="White">
    <color rgba="1.0 1.0 1.0 1.0"/>
  </material>
  <gazebo>
    <plugin filename="libgazebo_ros_control.so" name="ros_control">
      <robotSimType>gazebo_ros_control/DefaultRobotHWSim</robotSimType>
    </plugin>
  </gazebo>
  <!--  <xacro:macro_0x02000106 part_id="WR" hand_id="H0" parent="world" transmission="true">
    <origin xyz="0 0 0" rpy="0 0 0"/>
  </xacro:macro_0x02000106> -->
  <link name="H0_base_link">
    <inertial>
      <origin rpy="0 0 0" xyz="-8.6116E-06 -0.0058125 0.028294"/>
      <mass value="0.021"/>
      <inertia ixx="0.00014442" ixy="1.2033E-08" ixz="-5.9646E-10" iyy="0.00014979" iyz="-1.0288E-05" izz="5.2943E-05"/>
    </inertial>
    <visual>
      <origin rpy="0 0 0" xyz="0 0 0"/>
      <geometry>
        <mesh filename="package://fh_description/meshes/v2/palm_link.stl"/>
      </geometry>
      <material name="dark_grey">
        <color rgba="0.267 0.267 0.267 1.0"/>
      </material>
    </visual>
    <collision>
      <origin rpy="0 0 0" xyz="0 0 0"/>
      <geometry>
        <mesh filename="package://fh_description/meshes/v2/palm_link_col.stl"/>
      </geometry>
      <material name="dark_grey">
        <color rgba="0.267 0.267 0.267 1.0"/>
      </material>
    </collision>
  </link>
  <gazebo reference="H0_base_link">
    <material>Gazebo/DarkGrey</material>
  </gazebo>
  <joint name="H0Base" type="fixed">
    <origin rpy="0 0 0" xyz="0 0 0"/>
    <parent link="world"/>
    <child link="H0_wrist_attach"/>
  </joint>
  <link name="H0_insert_F0"/>
  <joint name="H0_dummy_joint_1" type="fixed">
    <origin rpy="0 0 2.3562" xyz="-0.045 -0.025981 0"/>
    <axis xyz="0 -1 0"/>
    <parent link="H0_base_link"/>
    <child link="H0_insert_F0"/>
  </joint>
  <link name="H0_insert_F1"/>
  <joint name="H0_dummy_joint_2" type="fixed">
    <origin rpy="0 0 0" xyz="0 0.029019 0"/>
    <axis xyz="0 -1 0"/>
    <parent link="H0_base_link"/>
    <child link="H0_insert_F1"/>
  </joint>
  <link name="H0_insert_F2"/>
  <joint name="H0_dummy_joint_3" type="fixed">
    <origin rpy="0 0 -2.3562" xyz="0.045 -0.025981 0"/>
    <axis xyz="0 -1 0"/>
    <parent link="H0_base_link"/>
    <child link="H0_insert_F2"/>
  </joint>
  <link name="H0_wrist_attach"/>
  <joint name="H0_base_link_wrist_attach" type="fixed">
    <origin rpy="0 0 0" xyz="0 0 -0.0005"/>
    <child link="H0_base_link"/>
    <parent link="H0_wrist_attach"/>
  </joint>
  <joint name="H0_ee_fixed_joint" type="fixed">
    <parent link="H0_base_link"/>
    <child link="fh_manipulator"/>
    <origin rpy="0.0 0.0 0.0" xyz="0.0 0.0 0.10"/>
  </joint>
  <link name="fh_manipulator"/>
  <link name="H0_F0_palm_link">
    <inertial>
      <origin rpy="0 0 0" xyz="-0.00681802120880393 -0.00947020456878004 0.067587996682422"/>
      <mass value="0.095"/>
      <inertia ixx="2.79747833772125E-05" ixy="-5.50900644725373E-08" ixz="-2.82072424927723E-07" iyy="2.67800858812928E-05" iyz="3.1953125069394E-06" izz="9.86122271726361E-06"/>
    </inertial>
    <visual>
      <origin rpy="0 0 0" xyz="0 0 0"/>
      <geometry>
        <mesh filename="package://fh_description/meshes/v2/finger_palm_link.stl"/>
      </geometry>
      <material name="dark_grey">
        <color rgba="0.267 0.267 0.267 1.0"/>
      </material>
    </visual>
    <!-- Collision mesh no needed as it is part of palm_link_col.stl collision mesh -->
    <!--xacro:mesh_collision file_name="v2/finger_palm_link.stl">
        <origin xyz="0 0 0" rpy="0 0 0" />
        <xacro:dark_grey/>
      </xacro:mesh_collision-->
  </link>
  <gazebo reference="H0_F0_palm_link">
    <material>Gazebo/DarkGrey</material>
  </gazebo>
  <link name="H0_F0_base_link">
    <inertial>
      <origin rpy="0 0 0" xyz="-0.00027 0.02711 0.06013"/>
      <mass value="0.416"/>
      <inertia ixx="0.00226490263" ixy="3.77717E-06" ixz="5.80703E-06" iyy="0.00193941498" iyz="6.9931504E-04" izz="0.00053136647"/>
    </inertial>
    <visual>
      <origin rpy="0 0 0" xyz="0 0 0"/>
      <geometry>
        <mesh filename="package://fh_description/meshes/v2/finger_base_link.stl"/>
      </geometry>
      <material name="dark_grey">
        <color rgba="0.267 0.267 0.267 1.0"/>
      </material>
    </visual>
    <collision>
      <origin rpy="0 0 0" xyz="0 0 0"/>
      <geometry>
        <mesh filename="package://fh_description/meshes/v2/finger_base_link_col.stl"/>
      </geometry>
      <material name="dark_grey">
        <color rgba="0.267 0.267 0.267 1.0"/>
      </material>
    </collision>
  </link>
  <gazebo reference="H0_F0_base_link">
    <material>Gazebo/DarkGrey</material>
  </gazebo>
  <link name="H0_F0_link_1">
    <inertial>
      <origin rpy="0 0 0" xyz="-0.00071 -0.00022 0.01415"/>
      <mass value="0.254"/>
      <inertia ixx="0.00019133634" ixy="-0.00000008786" ixz="-0.00000720119" iyy="0.00021397597" iyz="-0.00000201648" izz="0.00008396436"/>
    </inertial>
    <visual>
      <origin rpy="0 0 0" xyz="0 0 0"/>
      <geometry>
        <mesh filename="package://fh_description/meshes/v2/finger_prox_link.stl"/>
      </geometry>
      <material name="dark_grey">
        <color rgba="0.267 0.267 0.267 1.0"/>
      </material>
    </visual>
    <collision>
      <origin rpy="0 0 0" xyz="0 0 0"/>
      <geometry>
        <mesh filename="package://fh_description/meshes/v2/finger_prox_link_col.stl"/>
      </geometry>
      <material name="dark_grey">
        <color rgba="0.267 0.267 0.267 1.0"/>
      </material>
    </collision>
  </link>
  <gazebo reference="H0_F0_link_1">
    <material>Gazebo/DarkGrey</material>
  </gazebo>
  <link name="H0_F0_link_2">
    <inertial>
      <origin rpy="0 0 0" xyz="0.00197 -0.00166 0.00962"/>
      <mass value="0.071"/>
      <inertia ixx="0.0000351756" ixy="0.0000000072" ixz="0.00000014613" iyy="0.00003639824" iyz="-0.00000538058" izz="0.00001224172"/>
    </inertial>
    <visual>
      <origin rpy="0 0 0" xyz="0 0 0"/>
      <geometry>
        <mesh filename="package://fh_description/meshes/v2/finger_dist_link.stl"/>
      </geometry>
      <material name="dark_grey">
        <color rgba="0.267 0.267 0.267 1.0"/>
      </material>
    </visual>
    <collision>
      <origin rpy="0 0 0" xyz="0 0 0"/>
      <geometry>
        <mesh filename="package://fh_description/meshes/v2/finger_dist_link.stl"/>
      </geometry>
      <material name="dark_grey">
        <color rgba="0.267 0.267 0.267 1.0"/>
      </material>
    </collision>
  </link>
  <gazebo reference="H0_F0_link_2">
    <material>Gazebo/DarkGrey</material>
  </gazebo>
  <joint name="H0_F0Palm" type="fixed">
    <origin rpy="0 0 0" xyz="0 0 0"/>
    <parent link="H0_insert_F0"/>
    <child link="H0_F0_palm_link"/>
  </joint>
  <joint name="H0_F0J0" type="revolute">
    <origin rpy="-8.8818E-16 -1.0061E-16 0.022402" xyz="0 0 0.00016528"/>
    <axis xyz="0 0 1"/>
    <parent link="H0_F0_palm_link"/>
    <child link="H0_F0_base_link"/>
    <limit effort="2" lower="-0.785398163397" upper="0.785398163397" velocity="1.0"/>
    <dynamics damping="0.01"/>
  </joint>
  <joint name="H0_F0J1" type="revolute">
    <origin rpy="0.070695 6.9389E-16 2.0947E-16" xyz="0 0.035 0.11683"/>
    <axis xyz="1 0 0"/>
    <parent link="H0_F0_base_link"/>
    <child link="H0_F0_link_1"/>
    <limit effort="2" lower="-1.3962634016" upper="1.0471975512" velocity="1.0"/>
    <dynamics damping="0.1"/>
  </joint>
  <joint name="H0_F0J2" type="revolute">
    <origin rpy="-0.0068649 1.7347E-18 1.6176E-16" xyz="0 0 0.06"/>
    <axis xyz="1 0 0"/>
    <parent link="H0_F0_link_1"/>
    <child link="H0_F0_link_2"/>
    <limit effort="2" lower="-1.0471975512" upper="1.3962634016" velocity="1.0"/>
    <dynamics damping="0.01"/>
  </joint>
  <transmission name="H0_F0J0_transmission">
    <type>transmission_interface/SimpleTransmission</type>
    <actuator name="H0_F0J0">
      <mechanicalReduction>1</mechanicalReduction>
    </actuator>
    <joint name="H0_F0J0">
      <hardwareInterface>EffortJointInterface</hardwareInterface>
    </joint>
  </transmission>
  <transmission name="H0_F0J1_transmission">
    <type>transmission_interface/SimpleTransmission</type>
    <actuator name="H0_F0J1">
      <mechanicalReduction>1</mechanicalReduction>
    </actuator>
    <joint name="H0_F0J1">
      <hardwareInterface>EffortJointInterface</hardwareInterface>
    </joint>
  </transmission>
  <transmission name="H0_F0J2_transmission">
    <type>transmission_interface/SimpleTransmission</type>
    <actuator name="H0_F0J2">
      <mechanicalReduction>1</mechanicalReduction>
    </actuator>
    <joint name="H0_F0J2">
      <hardwareInterface>EffortJointInterface</hardwareInterface>
    </joint>
  </transmission>
  <link name="H0_F0_tip"/>
  <link name="H0_F0_optoforce"/>
  <joint name="H0_F0_tip_to_optoforce" type="fixed">
    <parent link="H0_F0_tip"/>
    <child link="H0_F0_optoforce"/>
    <origin rpy="-0.35 0 0" xyz="0 -0.006 0.046"/>
  </joint>
  <joint name="H0_F0_tip" type="fixed">
    <parent link="H0_F0_link_2"/>
    <child link="H0_F0_tip"/>
  </joint>
  <link name="H0_F1_palm_link">
    <inertial>
      <origin rpy="0 0 0" xyz="-0.00681802120880393 -0.00947020456878004 0.067587996682422"/>
      <mass value="0.095"/>
      <inertia ixx="2.79747833772125E-05" ixy="-5.50900644725373E-08" ixz="-2.82072424927723E-07" iyy="2.67800858812928E-05" iyz="3.1953125069394E-06" izz="9.86122271726361E-06"/>
    </inertial>
    <visual>
      <origin rpy="0 0 0" xyz="0 0 0"/>
      <geometry>
        <mesh filename="package://fh_description/meshes/v2/finger_palm_link.stl"/>
      </geometry>
      <material name="dark_grey">
        <color rgba="0.267 0.267 0.267 1.0"/>
      </material>
    </visual>
    <!-- Collision mesh no needed as it is part of palm_link_col.stl collision mesh -->
    <!--xacro:mesh_collision file_name="v2/finger_palm_link.stl">
        <origin xyz="0 0 0" rpy="0 0 0" />
        <xacro:dark_grey/>
      </xacro:mesh_collision-->
  </link>
  <gazebo reference="H0_F1_palm_link">
    <material>Gazebo/DarkGrey</material>
  </gazebo>
  <link name="H0_F1_base_link">
    <inertial>
      <origin rpy="0 0 0" xyz="-0.00027 0.02711 0.06013"/>
      <mass value="0.416"/>
      <inertia ixx="0.00226490263" ixy="3.77717E-06" ixz="5.80703E-06" iyy="0.00193941498" iyz="6.9931504E-04" izz="0.00053136647"/>
    </inertial>
    <visual>
      <origin rpy="0 0 0" xyz="0 0 0"/>
      <geometry>
        <mesh filename="package://fh_description/meshes/v2/finger_base_link.stl"/>
      </geometry>
      <material name="dark_grey">
        <color rgba="0.267 0.267 0.267 1.0"/>
      </material>
    </visual>
    <collision>
      <origin rpy="0 0 0" xyz="0 0 0"/>
      <geometry>
        <mesh filename="package://fh_description/meshes/v2/finger_base_link_col.stl"/>
      </geometry>
      <material name="dark_grey">
        <color rgba="0.267 0.267 0.267 1.0"/>
      </material>
    </collision>
  </link>
  <gazebo reference="H0_F1_base_link">
    <material>Gazebo/DarkGrey</material>
  </gazebo>
  <link name="H0_F1_link_1">
    <inertial>
      <origin rpy="0 0 0" xyz="-0.00071 -0.00022 0.01415"/>
      <mass value="0.254"/>
      <inertia ixx="0.00019133634" ixy="-0.00000008786" ixz="-0.00000720119" iyy="0.00021397597" iyz="-0.00000201648" izz="0.00008396436"/>
    </inertial>
    <visual>
      <origin rpy="0 0 0" xyz="0 0 0"/>
      <geometry>
        <mesh filename="package://fh_description/meshes/v2/finger_prox_link.stl"/>
      </geometry>
      <material name="dark_grey">
        <color rgba="0.267 0.267 0.267 1.0"/>
      </material>
    </visual>
    <collision>
      <origin rpy="0 0 0" xyz="0 0 0"/>
      <geometry>
        <mesh filename="package://fh_description/meshes/v2/finger_prox_link_col.stl"/>
      </geometry>
      <material name="dark_grey">
        <color rgba="0.267 0.267 0.267 1.0"/>
      </material>
    </collision>
  </link>
  <gazebo reference="H0_F1_link_1">
    <material>Gazebo/DarkGrey</material>
  </gazebo>
  <link name="H0_F1_link_2">
    <inertial>
      <origin rpy="0 0 0" xyz="0.00197 -0.00166 0.00962"/>
      <mass value="0.071"/>
      <inertia ixx="0.0000351756" ixy="0.0000000072" ixz="0.00000014613" iyy="0.00003639824" iyz="-0.00000538058" izz="0.00001224172"/>
    </inertial>
    <visual>
      <origin rpy="0 0 0" xyz="0 0 0"/>
      <geometry>
        <mesh filename="package://fh_description/meshes/v2/finger_dist_link.stl"/>
      </geometry>
      <material name="dark_grey">
        <color rgba="0.267 0.267 0.267 1.0"/>
      </material>
    </visual>
    <collision>
      <origin rpy="0 0 0" xyz="0 0 0"/>
      <geometry>
        <mesh filename="package://fh_description/meshes/v2/finger_dist_link.stl"/>
      </geometry>
      <material name="dark_grey">
        <color rgba="0.267 0.267 0.267 1.0"/>
      </material>
    </collision>
  </link>
  <gazebo reference="H0_F1_link_2">
    <material>Gazebo/DarkGrey</material>
  </gazebo>
  <joint name="H0_F1Palm" type="fixed">
    <origin rpy="0 0 0" xyz="0 0 0"/>
    <parent link="H0_insert_F1"/>
    <child link="H0_F1_palm_link"/>
  </joint>
  <joint name="H0_F1J0" type="revolute">
    <origin rpy="-8.8818E-16 -1.0061E-16 0.022402" xyz="0 0 0.00016528"/>
    <axis xyz="0 0 1"/>
    <parent link="H0_F1_palm_link"/>
    <child link="H0_F1_base_link"/>
    <limit effort="2" lower="-0.785398163397" upper="0.785398163397" velocity="1.0"/>
    <dynamics damping="0.01"/>
  </joint>
  <joint name="H0_F1J1" type="revolute">
    <origin rpy="0.070695 6.9389E-16 2.0947E-16" xyz="0 0.035 0.11683"/>
    <axis xyz="1 0 0"/>
    <parent link="H0_F1_base_link"/>
    <child link="H0_F1_link_1"/>
    <limit effort="2" lower="-1.3962634016" upper="1.0471975512" velocity="1.0"/>
    <dynamics damping="0.1"/>
  </joint>
  <joint name="H0_F1J2" type="revolute">
    <origin rpy="-0.0068649 1.7347E-18 1.6176E-16" xyz="0 0 0.06"/>
    <axis xyz="1 0 0"/>
    <parent link="H0_F1_link_1"/>
    <child link="H0_F1_link_2"/>
    <limit effort="2" lower="-1.0471975512" upper="1.3962634016" velocity="1.0"/>
    <dynamics damping="0.01"/>
  </joint>
  <transmission name="H0_F1J0_transmission">
    <type>transmission_interface/SimpleTransmission</type>
    <actuator name="H0_F1J0">
      <mechanicalReduction>1</mechanicalReduction>
    </actuator>
    <joint name="H0_F1J0">
      <hardwareInterface>EffortJointInterface</hardwareInterface>
    </joint>
  </transmission>
  <transmission name="H0_F1J1_transmission">
    <type>transmission_interface/SimpleTransmission</type>
    <actuator name="H0_F1J1">
      <mechanicalReduction>1</mechanicalReduction>
    </actuator>
    <joint name="H0_F1J1">
      <hardwareInterface>EffortJointInterface</hardwareInterface>
    </joint>
  </transmission>
  <transmission name="H0_F1J2_transmission">
    <type>transmission_interface/SimpleTransmission</type>
    <actuator name="H0_F1J2">
      <mechanicalReduction>1</mechanicalReduction>
    </actuator>
    <joint name="H0_F1J2">
      <hardwareInterface>EffortJointInterface</hardwareInterface>
    </joint>
  </transmission>
  <link name="H0_F1_tip"/>
  <link name="H0_F1_optoforce"/>
  <joint name="H0_F1_tip_to_optoforce" type="fixed">
    <parent link="H0_F1_tip"/>
    <child link="H0_F1_optoforce"/>
    <origin rpy="-0.35 0 0" xyz="0 -0.006 0.046"/>
  </joint>
  <joint name="H0_F1_tip" type="fixed">
    <parent link="H0_F1_link_2"/>
    <child link="H0_F1_tip"/>
  </joint>
  <link name="H0_F2_palm_link">
    <inertial>
      <origin rpy="0 0 0" xyz="-0.00681802120880393 -0.00947020456878004 0.067587996682422"/>
      <mass value="0.095"/>
      <inertia ixx="2.79747833772125E-05" ixy="-5.50900644725373E-08" ixz="-2.82072424927723E-07" iyy="2.67800858812928E-05" iyz="3.1953125069394E-06" izz="9.86122271726361E-06"/>
    </inertial>
    <visual>
      <origin rpy="0 0 0" xyz="0 0 0"/>
      <geometry>
        <mesh filename="package://fh_description/meshes/v2/finger_palm_link.stl"/>
      </geometry>
      <material name="dark_grey">
        <color rgba="0.267 0.267 0.267 1.0"/>
      </material>
    </visual>
    <!-- Collision mesh no needed as it is part of palm_link_col.stl collision mesh -->
    <!--xacro:mesh_collision file_name="v2/finger_palm_link.stl">
        <origin xyz="0 0 0" rpy="0 0 0" />
        <xacro:dark_grey/>
      </xacro:mesh_collision-->
  </link>
  <gazebo reference="H0_F2_palm_link">
    <material>Gazebo/DarkGrey</material>
  </gazebo>
  <link name="H0_F2_base_link">
    <inertial>
      <origin rpy="0 0 0" xyz="-0.00027 0.02711 0.06013"/>
      <mass value="0.416"/>
      <inertia ixx="0.00226490263" ixy="3.77717E-06" ixz="5.80703E-06" iyy="0.00193941498" iyz="6.9931504E-04" izz="0.00053136647"/>
    </inertial>
    <visual>
      <origin rpy="0 0 0" xyz="0 0 0"/>
      <geometry>
        <mesh filename="package://fh_description/meshes/v2/finger_base_link.stl"/>
      </geometry>
      <material name="dark_grey">
        <color rgba="0.267 0.267 0.267 1.0"/>
      </material>
    </visual>
    <collision>
      <origin rpy="0 0 0" xyz="0 0 0"/>
      <geometry>
        <mesh filename="package://fh_description/meshes/v2/finger_base_link_col.stl"/>
      </geometry>
      <material name="dark_grey">
        <color rgba="0.267 0.267 0.267 1.0"/>
      </material>
    </collision>
  </link>
  <gazebo reference="H0_F2_base_link">
    <material>Gazebo/DarkGrey</material>
  </gazebo>
  <link name="H0_F2_link_1">
    <inertial>
      <origin rpy="0 0 0" xyz="-0.00071 -0.00022 0.01415"/>
      <mass value="0.254"/>
      <inertia ixx="0.00019133634" ixy="-0.00000008786" ixz="-0.00000720119" iyy="0.00021397597" iyz="-0.00000201648" izz="0.00008396436"/>
    </inertial>
    <visual>
      <origin rpy="0 0 0" xyz="0 0 0"/>
      <geometry>
        <mesh filename="package://fh_description/meshes/v2/finger_prox_link.stl"/>
      </geometry>
      <material name="dark_grey">
        <color rgba="0.267 0.267 0.267 1.0"/>
      </material>
    </visual>
    <collision>
      <origin rpy="0 0 0" xyz="0 0 0"/>
      <geometry>
        <mesh filename="package://fh_description/meshes/v2/finger_prox_link_col.stl"/>
      </geometry>
      <material name="dark_grey">
        <color rgba="0.267 0.267 0.267 1.0"/>
      </material>
    </collision>
  </link>
  <gazebo reference="H0_F2_link_1">
    <material>Gazebo/DarkGrey</material>
  </gazebo>
  <link name="H0_F2_link_2">
    <inertial>
      <origin rpy="0 0 0" xyz="0.00197 -0.00166 0.00962"/>
      <mass value="0.071"/>
      <inertia ixx="0.0000351756" ixy="0.0000000072" ixz="0.00000014613" iyy="0.00003639824" iyz="-0.00000538058" izz="0.00001224172"/>
    </inertial>
    <visual>
      <origin rpy="0 0 0" xyz="0 0 0"/>
      <geometry>
        <mesh filename="package://fh_description/meshes/v2/finger_dist_link.stl"/>
      </geometry>
      <material name="dark_grey">
        <color rgba="0.267 0.267 0.267 1.0"/>
      </material>
    </visual>
    <collision>
      <origin rpy="0 0 0" xyz="0 0 0"/>
      <geometry>
        <mesh filename="package://fh_description/meshes/v2/finger_dist_link.stl"/>
      </geometry>
      <material name="dark_grey">
        <color rgba="0.267 0.267 0.267 1.0"/>
      </material>
    </collision>
  </link>
  <gazebo reference="H0_F2_link_2">
    <material>Gazebo/DarkGrey</material>
  </gazebo>
  <joint name="H0_F2Palm" type="fixed">
    <origin rpy="0 0 0" xyz="0 0 0"/>
    <parent link="H0_insert_F2"/>
    <child link="H0_F2_palm_link"/>
  </joint>
  <joint name="H0_F2J0" type="revolute">
    <origin rpy="-8.8818E-16 -1.0061E-16 0.022402" xyz="0 0 0.00016528"/>
    <axis xyz="0 0 1"/>
    <parent link="H0_F2_palm_link"/>
    <child link="H0_F2_base_link"/>
    <limit effort="2" lower="-0.785398163397" upper="0.785398163397" velocity="1.0"/>
    <dynamics damping="0.01"/>
  </joint>
  <joint name="H0_F2J1" type="revolute">
    <origin rpy="0.070695 6.9389E-16 2.0947E-16" xyz="0 0.035 0.11683"/>
    <axis xyz="1 0 0"/>
    <parent link="H0_F2_base_link"/>
    <child link="H0_F2_link_1"/>
    <limit effort="2" lower="-1.3962634016" upper="1.0471975512" velocity="1.0"/>
    <dynamics damping="0.1"/>
  </joint>
  <joint name="H0_F2J2" type="revolute">
    <origin rpy="-0.0068649 1.7347E-18 1.6176E-16" xyz="0 0 0.06"/>
    <axis xyz="1 0 0"/>
    <parent link="H0_F2_link_1"/>
    <child link="H0_F2_link_2"/>
    <limit effort="2" lower="-1.0471975512" upper="1.3962634016" velocity="1.0"/>
    <dynamics damping="0.01"/>
  </joint>
  <transmission name="H0_F2J0_transmission">
    <type>transmission_interface/SimpleTransmission</type>
    <actuator name="H0_F2J0">
      <mechanicalReduction>1</mechanicalReduction>
    </actuator>
    <joint name="H0_F2J0">
      <hardwareInterface>EffortJointInterface</hardwareInterface>
    </joint>
  </transmission>
  <transmission name="H0_F2J1_transmission">
    <type>transmission_interface/SimpleTransmission</type>
    <actuator name="H0_F2J1">
      <mechanicalReduction>1</mechanicalReduction>
    </actuator>
    <joint name="H0_F2J1">
      <hardwareInterface>EffortJointInterface</hardwareInterface>
    </joint>
  </transmission>
  <transmission name="H0_F2J2_transmission">
    <type>transmission_interface/SimpleTransmission</type>
    <actuator name="H0_F2J2">
      <mechanicalReduction>1</mechanicalReduction>
    </actuator>
    <joint name="H0_F2J2">
      <hardwareInterface>EffortJointInterface</hardwareInterface>
    </joint>
  </transmission>
  <link name="H0_F2_tip"/>
  <link name="H0_F2_optoforce"/>
  <joint name="H0_F2_tip_to_optoforce" type="fixed">
    <parent link="H0_F2_tip"/>
    <child link="H0_F2_optoforce"/>
    <origin rpy="-0.35 0 0" xyz="0 -0.006 0.046"/>
  </joint>
  <joint name="H0_F2_tip" type="fixed">
    <parent link="H0_F2_link_2"/>
    <child link="H0_F2_tip"/>
  </joint>
</robot>

