<mujoco model="hand_H_robot">
        <body name="ra_base_link" pos="0 0 0.1">
            <inertial pos="0 0 0" quat="0.5 0.5 -0.5 0.5" mass="4" diaginertia="0.01125 0.00610633 0.00610633" />
            <geom type="mesh" rgba="0.7 0.7 0.7 1" mesh="base" />
            <body name="ra_shoulder_link" pos="0 0 0.1273">
                <inertial pos="0 0 0" mass="7.778" diaginertia="0.0314743 0.0314743 0.0218756" />
                <joint name="ra_shoulder_pan_joint" pos="0 0 0" axis="0 0 1" limited="true" range="-6.28319 6.28319" />
                <geom type="mesh" rgba="0.7 0.7 0.7 1" mesh="shoulder" />
                <body name="ra_upper_arm_link" pos="0 0.220941 0" quat="0.707107 0 0.707107 0">
                    <inertial pos="0 0 0.306" mass="12.93" diaginertia="0.421754 0.421754 0.0363656" />
                    <joint name="ra_shoulder_lift_joint" pos="0 0 0" axis="0 1 0" limited="true" range="-6.28319 6.28319" />
                    <geom type="mesh" rgba="0.7 0.7 0.7 1" mesh="upperarm" />
                    <body name="ra_forearm_link" pos="0 -0.1719 0.612">
                        <inertial pos="0 0 0.28615" mass="3.87" diaginertia="0.11107 0.11107 0.0108844" />
                        <joint name="ra_elbow_joint" pos="0 0 0" axis="0 1 0" limited="true" range="-3.14159 3.14159" />
                        <geom type="mesh" rgba="0.7 0.7 0.7 1" mesh="forearm" />
                        <body name="ra_wrist_1_link" pos="0 0 0.5723" quat="0.707107 0 0.707107 0">
                            <inertial pos="0 0 0" quat="0.5 0.5 -0.5 0.5" mass="1.96" diaginertia="0.0055125 0.00510825 0.00510825" />
                            <joint name="ra_wrist_1_joint" pos="0 0 0" axis="0 1 0" limited="true" range="-6.28319 6.28319" />
                            <geom type="mesh" rgba="0.7 0.7 0.7 1" mesh="wrist1" />
                            <body name="ra_wrist_2_link" pos="0 0.1149 0">
                                <inertial pos="0 0 0" quat="0.5 0.5 -0.5 0.5" mass="1.96" diaginertia="0.0055125 0.00510825 0.00510825" />
                                <joint name="ra_wrist_2_joint" pos="0 0 0" axis="0 0 1" limited="true" range="-6.28319 6.28319" />
                                <geom type="mesh" rgba="0.7 0.7 0.7 1" mesh="wrist2" />
                                <body name="ra_wrist_3_link" pos="0 0 0.1157">
                                    <inertial pos="0 0 0" quat="0.5 0.5 -0.5 0.5" mass="0.202" diaginertia="0.000568125 0.000526462 0.000526462" />
                                    <joint name="ra_wrist_3_joint" pos="0 0 0" axis="0 1 0" limited="true" range="-6.28319 6.28319" />
                                    <geom type="mesh" rgba="0.7 0.7 0.7 1" mesh="wrist3" />
                                    <body name="ra_ee_link" pos="0 0.0922 0" quat="0.707107 0 0 0.707107">
                                        <inertial pos="-0.01 0 0" mass="0.001" diaginertia="1.66667e-08 1.66667e-08 1.66667e-08" />
                                        <geom size="0.005 0.005 0.005" pos="-0.01 0 0" type="box" />
                                        <body name="H0_mounting_plate" pos="0 0 0" quat="0.5 -0.5 0.5 -0.5">
                                            <inertial pos="1e-05 -0.00205 0.00473" quat="-0.0231886 0.706771 -0.0258015 0.706592" mass="0.02442" diaginertia="1.84436e-05 1.05691e-05 9.3075e-06" />
                                            <geom type="mesh" rgba="0.267 0.267 0.267 1" mesh="mount_link_50_4_M6_col" />
                                            <body name="H0_base_attach" pos="0 0 0.01">
                                                <inertial pos="0 0 0.01" mass="0" diaginertia="0 0 0" />
                                                <body name="H0_wrist_attach" pos="0 0 0">
                                                    <inertial pos="0 0 0" mass="0" diaginertia="0 0 0" />
                                                    <body name="H0_base_link" pos="0 0 -0.0005">
                                                        <inertial pos="-8.6116e-06 -0.0058125 0.028294" quat="0.706797 -0.0370276 0.0369536 0.70548" mass="0.021" diaginertia="0.000150871 0.00014442 5.18622e-05" />
                                                        <geom type="mesh" rgba="0.267 0.267 0.267 1" mesh="palm_link_col" friction="1 0.05 0.01" condim="4" margin="0.0005" contype="1" conaffinity="1"/>
                                                        <body name="H0_insert_F0" pos="-0.045 -0.025981 0" quat="0.382681 0 0 0.923881">
                                                            <inertial pos="-0.045 -0.025981 0" quat="0.382681 0 0 0.923881" mass="0" diaginertia="0 0 0" />
                                                            <body name="H0_F0_palm_link" pos="0 0 0">
                                                                <inertial pos="-0.00681802 -0.0094702 0.067588" quat="0.992601 0.0892342 0.0144943 -0.0810556" mass="0.095" diaginertia="2.7996e-05 2.73461e-05 9.27404e-06" />
                                                                <body name="H0_F0_base_link" pos="0 0 0.00016528" quat="0.999937 0 0 0.0112008">
                                                                    <inertial pos="-0.00027 0.02711 0.06013" quat="0.978249 0.193656 -0.0153906 0.0727275" mass="0.416" diaginertia="0.00226577 0.00222685 0.000243067" />
                                                                    <joint name="H0_F0J0" pos="0 0 0" axis="0 0 1" limited="true" range="-0.785398 0.785398" damping="0.5" armature="0.005" margin="0.01" frictionloss="0.001"/>
                                                                    <geom type="mesh" rgba="0.267 0.267 0.267 1" mesh="finger_base_link_col" friction="1 0.05 0.01" condim="4" margin="0.0005" contype="1" conaffinity="1"/>
                                                                    <body name="H0_F0_link_1" pos="0 0.035 0.11683" quat="0.999375 0.0353401 0 0">
                                                                        <inertial pos="-0.00071 -0.00022 0.01415" quat="0.707254 0.0180711 0.0290452 0.706132" mass="0.254" diaginertia="0.000214007 0.000191817 8.34524e-05" />
                                                                        <joint name="H0_F0J1" pos="0 0 0" axis="1 0 0" limited="true" range="-1.39626 1.0472" damping="0.5" armature="0.005" margin="0.01" frictionloss="0.001"/>
                                                                        <geom type="mesh" rgba="0.267 0.267 0.267 1" mesh="finger_prox_link_col" friction="1 0.05 0.01" condim="4" margin="0.0005" contype="1" conaffinity="1"/>
                                                                        <body name="H0_F0_link_2" pos="0 0 0.06" quat="0.999994 -0.00343244 0 0">
                                                                            <inertial pos="0.00197 -0.00166 0.00962" quat="0.699525 -0.0757005 0.0722124 0.706909" mass="0.071" diaginertia="3.75427e-05 3.51762e-05 1.10966e-05" />
                                                                            <joint name="H0_F0J2" pos="0 0 0" axis="1 0 0" limited="true" range="-1.0472 1.39626" damping="0.5" armature="0.005" margin="0.01" frictionloss="0.001"/>
                                                                            <geom type="mesh" rgba="0.267 0.267 0.267 1" mesh="finger_dist_link" friction="1 0.05 0.01" condim="4" margin="0.0005" contype="1" conaffinity="1"/>
                                                                            <body name="H0_F0_tip" pos="0 0 0">
                                                                                <inertial pos="0 0 0" mass="0" diaginertia="0 0 0" />
                                                                                <body name="H0_F0_optoforce" pos="0 -0.006 0.046" quat="0.984727 -0.174108 0 0">
                                                                                    <inertial pos="0 -0.006 0.046" quat="0.984727 -0.174108 0 0" mass="0" diaginertia="0 0 0" />
                                                                                </body>
                                                                            </body>
                                                                        </body>
                                                                    </body>
                                                                </body>
                                                            </body>
                                                        </body>
                                                        <body name="H0_insert_F1" pos="0 0.029019 0">
                                                            <inertial pos="0 0.029019 0" mass="0" diaginertia="0 0 0" />
                                                            <body name="H0_F1_palm_link" pos="0 0 0">
                                                                <inertial pos="-0.00681802 -0.0094702 0.067588" quat="0.992601 0.0892342 0.0144943 -0.0810556" mass="0.095" diaginertia="2.7996e-05 2.73461e-05 9.27404e-06" />
                                                                <body name="H0_F1_base_link" pos="0 0 0.00016528" quat="0.999937 0 0 0.0112008">
                                                                    <inertial pos="-0.00027 0.02711 0.06013" quat="0.978249 0.193656 -0.0153906 0.0727275" mass="0.416" diaginertia="0.00226577 0.00222685 0.000243067" />
                                                                    <joint name="H0_F1J0" pos="0 0 0" axis="0 0 1" limited="true" range="-0.785398 0.785398" damping="0.5" armature="0.005" margin="0.01" frictionloss="0.001"/>
                                                                    <geom type="mesh" rgba="0.267 0.267 0.267 1" mesh="finger_base_link_col" friction="1 0.05 0.01" condim="4" margin="0.0005" contype="1" conaffinity="1"/>
                                                                    <body name="H0_F1_link_1" pos="0 0.035 0.11683" quat="0.999375 0.0353401 0 0">
                                                                        <inertial pos="-0.00071 -0.00022 0.01415" quat="0.707254 0.0180711 0.0290452 0.706132" mass="0.254" diaginertia="0.000214007 0.000191817 8.34524e-05" />
                                                                        <joint name="H0_F1J1" pos="0 0 0" axis="1 0 0" limited="true" range="-1.39626 1.0472" damping="0.5" armature="0.005" margin="0.01" frictionloss="0.001"/>
                                                                        <geom type="mesh" rgba="0.267 0.267 0.267 1" mesh="finger_prox_link_col" friction="1 0.05 0.01" condim="4" margin="0.0005" contype="1" conaffinity="1"/>
                                                                        <body name="H0_F1_link_2" pos="0 0 0.06" quat="0.999994 -0.00343244 0 0">
                                                                            <inertial pos="0.00197 -0.00166 0.00962" quat="0.699525 -0.0757005 0.0722124 0.706909" mass="0.071" diaginertia="3.75427e-05 3.51762e-05 1.10966e-05" />
                                                                            <joint name="H0_F1J2" pos="0 0 0" axis="1 0 0" limited="true" range="-1.0472 1.39626" damping="0.5" armature="0.005" margin="0.01" frictionloss="0.001"/>
                                                                            <geom type="mesh" rgba="0.267 0.267 0.267 1" mesh="finger_dist_link" friction="1 0.05 0.01" condim="4" margin="0.0005" contype="1" conaffinity="1"/>
                                                                            <body name="H0_F1_tip" pos="0 0 0">
                                                                                <inertial pos="0 0 0" mass="0" diaginertia="0 0 0" />
                                                                                <body name="H0_F1_optoforce" pos="0 -0.006 0.046" quat="0.984727 -0.174108 0 0">
                                                                                    <inertial pos="0 -0.006 0.046" quat="0.984727 -0.174108 0 0" mass="0" diaginertia="0 0 0" />
                                                                                </body>
                                                                            </body>
                                                                        </body>
                                                                    </body>
                                                                </body>
                                                            </body>
                                                        </body>
                                                        <body name="H0_insert_F2" pos="0.045 -0.025981 0" quat="0.382681 0 0 -0.923881">
                                                            <inertial pos="0.045 -0.025981 0" quat="0.382681 0 0 -0.923881" mass="0" diaginertia="0 0 0" />
                                                            <body name="H0_F2_palm_link" pos="0 0 0">
                                                                <inertial pos="-0.00681802 -0.0094702 0.067588" quat="0.992601 0.0892342 0.0144943 -0.0810556" mass="0.095" diaginertia="2.7996e-05 2.73461e-05 9.27404e-06" />
                                                                <body name="H0_F2_base_link" pos="0 0 0.00016528" quat="0.999937 0 0 0.0112008">
                                                                    <inertial pos="-0.00027 0.02711 0.06013" quat="0.978249 0.193656 -0.0153906 0.0727275" mass="0.416" diaginertia="0.00226577 0.00222685 0.000243067" />
                                                                    <joint name="H0_F2J0" pos="0 0 0" axis="0 0 1" limited="true" range="-0.785398 0.785398" damping="0.5" armature="0.005" margin="0.01" frictionloss="0.001"/>
                                                                    <geom type="mesh" rgba="0.267 0.267 0.267 1" mesh="finger_base_link_col" friction="1 0.05 0.01" condim="4" margin="0.0005" contype="1" conaffinity="1"/>
                                                                    <body name="H0_F2_link_1" pos="0 0.035 0.11683" quat="0.999375 0.0353401 0 0">
                                                                        <inertial pos="-0.00071 -0.00022 0.01415" quat="0.707254 0.0180711 0.0290452 0.706132" mass="0.254" diaginertia="0.000214007 0.000191817 8.34524e-05" />
                                                                        <joint name="H0_F2J1" pos="0 0 0" axis="1 0 0" limited="true" range="-1.39626 1.0472" damping="0.5" armature="0.005" margin="0.01" frictionloss="0.001"/>
                                                                        <geom type="mesh" rgba="0.267 0.267 0.267 1" mesh="finger_prox_link_col" friction="1 0.05 0.01" condim="4" margin="0.0005" contype="1" conaffinity="1"/>
                                                                        <body name="H0_F2_link_2" pos="0 0 0.06" quat="0.999994 -0.00343244 0 0">
                                                                            <inertial pos="0.00197 -0.00166 0.00962" quat="0.699525 -0.0757005 0.0722124 0.706909" mass="0.071" diaginertia="3.75427e-05 3.51762e-05 1.10966e-05" />
                                                                            <joint name="H0_F2J2" pos="0 0 0" axis="1 0 0" limited="true" range="-1.0472 1.39626" damping="0.5" armature="0.005" margin="0.01" frictionloss="0.001"/>
                                                                            <geom type="mesh" rgba="0.267 0.267 0.267 1" mesh="finger_dist_link" friction="1 0.05 0.01" condim="4" margin="0.0005" contype="1" conaffinity="1"/>
                                                                            <body name="H0_F2_tip" pos="0 0 0">
                                                                                <inertial pos="0 0 0" mass="0" diaginertia="0 0 0" />
                                                                                <body name="H0_F2_optoforce" pos="0 -0.006 0.046" quat="0.984727 -0.174108 0 0">
                                                                                    <inertial pos="0 -0.006 0.046" quat="0.984727 -0.174108 0 0" mass="0" diaginertia="0 0 0" />
                                                                                </body>
                                                                            </body>
                                                                        </body>
                                                                    </body>
                                                                </body>
                                                            </body>
                                                        </body>
                                                        <body name="fh_manipulator" pos="0 0 0.1">
                                                            <inertial pos="0 0 0.1" mass="0" diaginertia="0 0 0" />
                                                        </body>
                                                    </body>
                                                </body>
                                            </body>
                                        </body>
                                    </body>
                                    <body name="ra_tool0" pos="0 0.0922 0" quat="0.707107 -0.707107 0 0">
                                        <inertial pos="0 0.0922 0" quat="0.707107 -0.707107 0 0" mass="0" diaginertia="0 0 0" />
                                    </body>
                                </body>
                            </body>
                        </body>
                    </body>
                </body>
            </body>
            <body name="ra_base" pos="0 0 0" quat="1.7949e-09 0 0 -1">
                <inertial pos="0 0 0" quat="1.7949e-09 0 0 -1" mass="0" diaginertia="0 0 0" />
            </body>
        </body>
</mujoco>
