<?xml version="1.0" ?>
<!-- =================================================================================== -->
<!-- |    This document was autogenerated by xacro from /home/user/projects/shadow_robot/base/src/fh_interface/fh_2_ur10_moveit_config/config/fh_v2_ur10_with_hand.urdf.xacro | -->
<!-- |    EDITING THIS FILE BY HAND IS NOT RECOMMENDED                                 | -->
<!-- =================================================================================== -->
<robot name="hand_H_robot" xmlns:xacro="http://ros.org/wiki/xacro">
  <!--
  Author: Kelsey Hawkins
  Contributers: Jimmy Da Silva, Ajit Krisshna N L, Muhammad Asif Rana
-->
  <!-- measured from model -->
  <mujoco> 
	 <compiler meshdir="meshes/visual/" intertiafromgeom=""/>
  </mujoco>
  <link name="world"/>
  <joint name="world_joint" type="fixed">
    <parent link="world"/>
    <child link="ra_base_link"/>
    <origin rpy="0.0 0.0 0.0" xyz="0.0 0.0 0.1"/>
  </joint>
  <link name="ra_base_link">
    <visual>
      <geometry>
        <mesh filename="package://ur_description/meshes/ur10/visual/base.dae"/>
      </geometry>
      <material name="LightGrey">
        <color rgba="0.7 0.7 0.7 1.0"/>
      </material>
    </visual>
    <collision>
      <geometry>
        <mesh filename="package://ur_description/meshes/ur10/collision/base.stl"/>
      </geometry>
    </collision>
    <inertial>
      <mass value="4.0"/>
      <origin rpy="0 0 0" xyz="0.0 0.0 0.0"/>
      <inertia ixx="0.0061063308908" ixy="0.0" ixz="0.0" iyy="0.0061063308908" iyz="0.0" izz="0.01125"/>
    </inertial>
  </link>
  <joint name="ra_shoulder_pan_joint" type="revolute">
    <parent link="ra_base_link"/>
    <child link="ra_shoulder_link"/>
    <origin rpy="0.0 0.0 0.0" xyz="0.0 0.0 0.1273"/>
    <axis xyz="0 0 1"/>
    <limit effort="330.0" lower="-6.2831853" upper="6.2831853" velocity="2.16"/>
    <dynamics damping="0.0" friction="0.0"/>
  </joint>
  <link name="ra_shoulder_link">
    <visual>
      <geometry>
        <mesh filename="package://ur_description/meshes/ur10/visual/shoulder.dae"/>
      </geometry>
      <material name="LightGrey">
        <color rgba="0.7 0.7 0.7 1.0"/>
      </material>
    </visual>
    <collision>
      <geometry>
        <mesh filename="package://ur_description/meshes/ur10/collision/shoulder.stl"/>
      </geometry>
    </collision>
    <inertial>
      <mass value="7.778"/>
      <origin rpy="0 0 0" xyz="0.0 0.0 0.0"/>
      <inertia ixx="0.0314743125769" ixy="0.0" ixz="0.0" iyy="0.0314743125769" iyz="0.0" izz="0.021875625"/>
    </inertial>
  </link>
  <joint name="ra_shoulder_lift_joint" type="revolute">
    <parent link="ra_shoulder_link"/>
    <child link="ra_upper_arm_link"/>
    <origin rpy="0.0 1.570796325 0.0" xyz="0.0 0.220941 0.0"/>
    <axis xyz="0 1 0"/>
    <limit effort="330.0" lower="-6.2831853" upper="6.2831853" velocity="2.16"/>
    <dynamics damping="0.0" friction="0.0"/>
  </joint>
  <link name="ra_upper_arm_link">
    <visual>
      <geometry>
        <mesh filename="package://ur_description/meshes/ur10/visual/upperarm.dae"/>
      </geometry>
      <material name="LightGrey">
        <color rgba="0.7 0.7 0.7 1.0"/>
      </material>
    </visual>
    <collision>
      <geometry>
        <mesh filename="package://ur_description/meshes/ur10/collision/upperarm.stl"/>
      </geometry>
    </collision>
    <inertial>
      <mass value="12.93"/>
      <origin rpy="0 0 0" xyz="0.0 0.0 0.306"/>
      <inertia ixx="0.421753803798" ixy="0.0" ixz="0.0" iyy="0.421753803798" iyz="0.0" izz="0.036365625"/>
    </inertial>
  </link>
  <joint name="ra_elbow_joint" type="revolute">
    <parent link="ra_upper_arm_link"/>
    <child link="ra_forearm_link"/>
    <origin rpy="0.0 0.0 0.0" xyz="0.0 -0.1719 0.612"/>
    <axis xyz="0 1 0"/>
    <limit effort="150.0" lower="-3.14159265" upper="3.14159265" velocity="3.15"/>
    <dynamics damping="0.0" friction="0.0"/>
  </joint>
  <link name="ra_forearm_link">
    <visual>
      <geometry>
        <mesh filename="package://ur_description/meshes/ur10/visual/forearm.dae"/>
      </geometry>
      <material name="LightGrey">
        <color rgba="0.7 0.7 0.7 1.0"/>
      </material>
    </visual>
    <collision>
      <geometry>
        <mesh filename="package://ur_description/meshes/ur10/collision/forearm.stl"/>
      </geometry>
    </collision>
    <inertial>
      <mass value="3.87"/>
      <origin rpy="0 0 0" xyz="0.0 0.0 0.28615"/>
      <inertia ixx="0.111069694097" ixy="0.0" ixz="0.0" iyy="0.111069694097" iyz="0.0" izz="0.010884375"/>
    </inertial>
  </link>
  <joint name="ra_wrist_1_joint" type="revolute">
    <parent link="ra_forearm_link"/>
    <child link="ra_wrist_1_link"/>
    <origin rpy="0.0 1.570796325 0.0" xyz="0.0 0.0 0.5723"/>
    <axis xyz="0 1 0"/>
    <limit effort="54.0" lower="-6.2831853" upper="6.2831853" velocity="3.2"/>
    <dynamics damping="0.0" friction="0.0"/>
  </joint>
  <link name="ra_wrist_1_link">
    <visual>
      <geometry>
        <mesh filename="package://ur_description/meshes/ur10/visual/wrist1.dae"/>
      </geometry>
      <material name="LightGrey">
        <color rgba="0.7 0.7 0.7 1.0"/>
      </material>
    </visual>
    <collision>
      <geometry>
        <mesh filename="package://ur_description/meshes/ur10/collision/wrist1.stl"/>
      </geometry>
    </collision>
    <inertial>
      <mass value="1.96"/>
      <origin rpy="0 0 0" xyz="0.0 0.0 0.0"/>
      <inertia ixx="0.0051082479567" ixy="0.0" ixz="0.0" iyy="0.0051082479567" iyz="0.0" izz="0.0055125"/>
    </inertial>
  </link>
  <joint name="ra_wrist_2_joint" type="revolute">
    <parent link="ra_wrist_1_link"/>
    <child link="ra_wrist_2_link"/>
    <origin rpy="0.0 0.0 0.0" xyz="0.0 0.1149 0.0"/>
    <axis xyz="0 0 1"/>
    <limit effort="54.0" lower="-6.2831853" upper="6.2831853" velocity="3.2"/>
    <dynamics damping="0.0" friction="0.0"/>
  </joint>
  <link name="ra_wrist_2_link">
    <visual>
      <geometry>
        <mesh filename="package://ur_description/meshes/ur10/visual/wrist2.dae"/>
      </geometry>
      <material name="LightGrey">
        <color rgba="0.7 0.7 0.7 1.0"/>
      </material>
    </visual>
    <collision>
      <geometry>
        <mesh filename="package://ur_description/meshes/ur10/collision/wrist2.stl"/>
      </geometry>
    </collision>
    <inertial>
      <mass value="1.96"/>
      <origin rpy="0 0 0" xyz="0.0 0.0 0.0"/>
      <inertia ixx="0.0051082479567" ixy="0.0" ixz="0.0" iyy="0.0051082479567" iyz="0.0" izz="0.0055125"/>
    </inertial>
  </link>
  <joint name="ra_wrist_3_joint" type="revolute">
    <parent link="ra_wrist_2_link"/>
    <child link="ra_wrist_3_link"/>
    <origin rpy="0.0 0.0 0.0" xyz="0.0 0.0 0.1157"/>
    <axis xyz="0 1 0"/>
    <limit effort="54.0" lower="-6.2831853" upper="6.2831853" velocity="3.2"/>
    <dynamics damping="0.0" friction="0.0"/>
  </joint>
  <link name="ra_wrist_3_link">
    <visual>
      <geometry>
        <mesh filename="package://ur_description/meshes/ur10/visual/wrist3.dae"/>
      </geometry>
      <material name="LightGrey">
        <color rgba="0.7 0.7 0.7 1.0"/>
      </material>
    </visual>
    <collision>
      <geometry>
        <mesh filename="package://ur_description/meshes/ur10/collision/wrist3.stl"/>
      </geometry>
    </collision>
    <inertial>
      <mass value="0.202"/>
      <origin rpy="0 0 0" xyz="0.0 0.0 0.0"/>
      <inertia ixx="0.000526462289415" ixy="0.0" ixz="0.0" iyy="0.000526462289415" iyz="0.0" izz="0.000568125"/>
    </inertial>
  </link>
  <joint name="ra_ee_fixed_joint" type="fixed">
    <parent link="ra_wrist_3_link"/>
    <child link="ra_ee_link"/>
    <origin rpy="0.0 0.0 1.570796325" xyz="0.0 0.0922 0.0"/>
  </joint>
  <link name="ra_ee_link">
    <collision>
      <geometry>
        <box size="0.01 0.01 0.01"/>
      </geometry>
      <origin rpy="0 0 0" xyz="-0.01 0 0"/>
    </collision>
  </link>
  <transmission name="ra_shoulder_pan_trans">
    <type>transmission_interface/SimpleTransmission</type>
    <joint name="ra_shoulder_pan_joint">
      <hardwareInterface>PositionJointInterface</hardwareInterface>
    </joint>
    <actuator name="ra_shoulder_pan_motor">
      <mechanicalReduction>1</mechanicalReduction>
    </actuator>
  </transmission>
  <transmission name="ra_shoulder_lift_trans">
    <type>transmission_interface/SimpleTransmission</type>
    <joint name="ra_shoulder_lift_joint">
      <hardwareInterface>PositionJointInterface</hardwareInterface>
    </joint>
    <actuator name="ra_shoulder_lift_motor">
      <mechanicalReduction>1</mechanicalReduction>
    </actuator>
  </transmission>
  <transmission name="ra_elbow_trans">
    <type>transmission_interface/SimpleTransmission</type>
    <joint name="ra_elbow_joint">
      <hardwareInterface>PositionJointInterface</hardwareInterface>
    </joint>
    <actuator name="ra_elbow_motor">
      <mechanicalReduction>1</mechanicalReduction>
    </actuator>
  </transmission>
  <transmission name="ra_wrist_1_trans">
    <type>transmission_interface/SimpleTransmission</type>
    <joint name="ra_wrist_1_joint">
      <hardwareInterface>PositionJointInterface</hardwareInterface>
    </joint>
    <actuator name="ra_wrist_1_motor">
      <mechanicalReduction>1</mechanicalReduction>
    </actuator>
  </transmission>
  <transmission name="ra_wrist_2_trans">
    <type>transmission_interface/SimpleTransmission</type>
    <joint name="ra_wrist_2_joint">
      <hardwareInterface>PositionJointInterface</hardwareInterface>
    </joint>
    <actuator name="ra_wrist_2_motor">
      <mechanicalReduction>1</mechanicalReduction>
    </actuator>
  </transmission>
  <transmission name="ra_wrist_3_trans">
    <type>transmission_interface/SimpleTransmission</type>
    <joint name="ra_wrist_3_joint">
      <hardwareInterface>PositionJointInterface</hardwareInterface>
    </joint>
    <actuator name="ra_wrist_3_motor">
      <mechanicalReduction>1</mechanicalReduction>
    </actuator>
  </transmission>
  <!-- nothing to do here at the moment -->
  <!-- ROS base_link to UR 'Base' Coordinates transform -->
  <link name="ra_base"/>
  <joint name="ra_base_link-base_fixed_joint" type="fixed">
    <!-- NOTE: this rotation is only needed as long as base_link itself is
                 not corrected wrt the real robot (ie: rotated over 180
                 degrees)
      -->
    <origin rpy="0 0 -3.14159265" xyz="0 0 0"/>
    <parent link="ra_base_link"/>
    <child link="ra_base"/>
  </joint>
  <!-- Frame coincident with all-zeros TCP on UR controller -->
  <link name="ra_tool0"/>
  <joint name="ra_wrist_3_link-tool0_fixed_joint" type="fixed">
    <origin rpy="-1.570796325 0 0" xyz="0 0.0922 0"/>
    <parent link="ra_wrist_3_link"/>
    <child link="ra_tool0"/>
  </joint>
  <link name="H0_base_attach"/>
  <material name="Blue">
    <color rgba="0.0 0.0 0.8 1.0"/>
  </material>
  <material name="Green">
    <color rgba="0.0 0.8 0.0 1.0"/>
  </material>
  <material name="BiotacGreen">
    <color rgba="0.31 0.85 0.42 1.0"/>
  </material>
  <material name="Grey">
    <color rgba="0.2 0.2 0.2 1.0"/>
  </material>
  <material name="LightGrey">
    <color rgba="0.6 0.6 0.6 1.0"/>
  </material>
  <material name="Red">
    <color rgba="0.8 0.0 0.0 1.0"/>
  </material>
  <material name="White">
    <color rgba="1.0 1.0 1.0 1.0"/>
  </material>
  <gazebo>
    <plugin filename="libgazebo_ros_control.so" name="ros_control">
      <robotSimType>gazebo_ros_control/DefaultRobotHWSim</robotSimType>
    </plugin>
  </gazebo>
  <link name="H0_base_link">
    <inertial>
      <origin rpy="0 0 0" xyz="-8.6116E-06 -0.0058125 0.028294"/>
      <mass value="0.021"/>
      <inertia ixx="0.00014442" ixy="1.2033E-08" ixz="-5.9646E-10" iyy="0.00014979" iyz="-1.0288E-05" izz="5.2943E-05"/>
    </inertial>
    <visual>
      <origin rpy="0 0 0" xyz="0 0 0"/>
      <geometry>
        <mesh filename="package://fh_description/meshes/v2/palm_link.stl"/>
      </geometry>
      <material name="dark_grey">
        <color rgba="0.267 0.267 0.267 1.0"/>
      </material>
    </visual>
    <collision>
      <origin rpy="0 0 0" xyz="0 0 0"/>
      <geometry>
        <mesh filename="package://fh_description/meshes/v2/palm_link_col.stl"/>
      </geometry>
      <material name="dark_grey">
        <color rgba="0.267 0.267 0.267 1.0"/>
      </material>
    </collision>
  </link>
  <gazebo reference="H0_base_link">
    <material>Gazebo/DarkGrey</material>
  </gazebo>
  <joint name="H0Base" type="fixed">
    <origin rpy="0 0 0" xyz="0 0 0"/>
    <parent link="H0_base_attach"/>
    <child link="H0_wrist_attach"/>
  </joint>
  <link name="H0_insert_F0"/>
  <joint name="H0_dummy_joint_1" type="fixed">
    <origin rpy="0 0 2.3562" xyz="-0.045 -0.025981 0"/>
    <axis xyz="0 -1 0"/>
    <parent link="H0_base_link"/>
    <child link="H0_insert_F0"/>
  </joint>
  <link name="H0_insert_F1"/>
  <joint name="H0_dummy_joint_2" type="fixed">
    <origin rpy="0 0 0" xyz="0 0.029019 0"/>
    <axis xyz="0 -1 0"/>
    <parent link="H0_base_link"/>
    <child link="H0_insert_F1"/>
  </joint>
  <link name="H0_insert_F2"/>
  <joint name="H0_dummy_joint_3" type="fixed">
    <origin rpy="0 0 -2.3562" xyz="0.045 -0.025981 0"/>
    <axis xyz="0 -1 0"/>
    <parent link="H0_base_link"/>
    <child link="H0_insert_F2"/>
  </joint>
  <link name="H0_wrist_attach"/>
  <joint name="H0_base_link_wrist_attach" type="fixed">
    <origin rpy="0 0 0" xyz="0 0 -0.0005"/>
    <child link="H0_base_link"/>
    <parent link="H0_wrist_attach"/>
  </joint>
  <joint name="H0_ee_fixed_joint" type="fixed">
    <parent link="H0_base_link"/>
    <child link="fh_manipulator"/>
    <origin rpy="0.0 0.0 0.0" xyz="0.0 0.0 0.10"/>
  </joint>
  <link name="fh_manipulator"/>
  <link name="H0_F0_palm_link">
    <inertial>
      <origin rpy="0 0 0" xyz="-0.00681802120880393 -0.00947020456878004 0.067587996682422"/>
      <mass value="0.095"/>
      <inertia ixx="2.79747833772125E-05" ixy="-5.50900644725373E-08" ixz="-2.82072424927723E-07" iyy="2.67800858812928E-05" iyz="3.1953125069394E-06" izz="9.86122271726361E-06"/>
    </inertial>
    <visual>
      <origin rpy="0 0 0" xyz="0 0 0"/>
      <geometry>
        <mesh filename="package://fh_description/meshes/v2/finger_palm_link.stl"/>
      </geometry>
      <material name="dark_grey">
        <color rgba="0.267 0.267 0.267 1.0"/>
      </material>
    </visual>
    <!-- Collision mesh no needed as it is part of palm_link_col.stl collision mesh -->
    <!--xacro:mesh_collision file_name="v2/finger_palm_link.stl">
        <origin xyz="0 0 0" rpy="0 0 0" />
        <xacro:dark_grey/>
      </xacro:mesh_collision-->
  </link>
  <gazebo reference="H0_F0_palm_link">
    <material>Gazebo/DarkGrey</material>
  </gazebo>
  <link name="H0_F0_base_link">
    <inertial>
      <origin rpy="0 0 0" xyz="-0.00027 0.02711 0.06013"/>
      <mass value="0.416"/>
      <inertia ixx="0.00226490263" ixy="3.77717E-06" ixz="5.80703E-06" iyy="0.00193941498" iyz="6.9931504E-04" izz="0.00053136647"/>
    </inertial>
    <visual>
      <origin rpy="0 0 0" xyz="0 0 0"/>
      <geometry>
        <mesh filename="package://fh_description/meshes/v2/finger_base_link.stl"/>
      </geometry>
      <material name="dark_grey">
        <color rgba="0.267 0.267 0.267 1.0"/>
      </material>
    </visual>
    <collision>
      <origin rpy="0 0 0" xyz="0 0 0"/>
      <geometry>
        <mesh filename="package://fh_description/meshes/v2/finger_base_link_col.stl"/>
      </geometry>
      <material name="dark_grey">
        <color rgba="0.267 0.267 0.267 1.0"/>
      </material>
    </collision>
  </link>
  <gazebo reference="H0_F0_base_link">
    <material>Gazebo/DarkGrey</material>
  </gazebo>
  <link name="H0_F0_link_1">
    <inertial>
      <origin rpy="0 0 0" xyz="-0.00071 -0.00022 0.01415"/>
      <mass value="0.254"/>
      <inertia ixx="0.00019133634" ixy="-0.00000008786" ixz="-0.00000720119" iyy="0.00021397597" iyz="-0.00000201648" izz="0.00008396436"/>
    </inertial>
    <visual>
      <origin rpy="0 0 0" xyz="0 0 0"/>
      <geometry>
        <mesh filename="package://fh_description/meshes/v2/finger_prox_link.stl"/>
      </geometry>
      <material name="dark_grey">
        <color rgba="0.267 0.267 0.267 1.0"/>
      </material>
    </visual>
    <collision>
      <origin rpy="0 0 0" xyz="0 0 0"/>
      <geometry>
        <mesh filename="package://fh_description/meshes/v2/finger_prox_link_col.stl"/>
      </geometry>
      <material name="dark_grey">
        <color rgba="0.267 0.267 0.267 1.0"/>
      </material>
    </collision>
  </link>
  <gazebo reference="H0_F0_link_1">
    <material>Gazebo/DarkGrey</material>
  </gazebo>
  <link name="H0_F0_link_2">
    <inertial>
      <origin rpy="0 0 0" xyz="0.00197 -0.00166 0.00962"/>
      <mass value="0.071"/>
      <inertia ixx="0.0000351756" ixy="0.0000000072" ixz="0.00000014613" iyy="0.00003639824" iyz="-0.00000538058" izz="0.00001224172"/>
    </inertial>
    <visual>
      <origin rpy="0 0 0" xyz="0 0 0"/>
      <geometry>
        <mesh filename="package://fh_description/meshes/v2/finger_dist_link.stl"/>
      </geometry>
      <material name="dark_grey">
        <color rgba="0.267 0.267 0.267 1.0"/>
      </material>
    </visual>
    <collision>
      <origin rpy="0 0 0" xyz="0 0 0"/>
      <geometry>
        <mesh filename="package://fh_description/meshes/v2/finger_dist_link.stl"/>
      </geometry>
      <material name="dark_grey">
        <color rgba="0.267 0.267 0.267 1.0"/>
      </material>
    </collision>
  </link>
  <gazebo reference="H0_F0_link_2">
    <material>Gazebo/DarkGrey</material>
  </gazebo>
  <joint name="H0_F0Palm" type="fixed">
    <origin rpy="0 0 0" xyz="0 0 0"/>
    <parent link="H0_insert_F0"/>
    <child link="H0_F0_palm_link"/>
  </joint>
  <joint name="H0_F0J0" type="revolute">
    <origin rpy="-8.8818E-16 -1.0061E-16 0.022402" xyz="0 0 0.00016528"/>
    <axis xyz="0 0 1"/>
    <parent link="H0_F0_palm_link"/>
    <child link="H0_F0_base_link"/>
    <limit effort="2" lower="-0.7853981625" upper="0.7853981625" velocity="1.0"/>
    <dynamics damping="0.01"/>
  </joint>
  <joint name="H0_F0J1" type="revolute">
    <origin rpy="0.070695 6.9389E-16 2.0947E-16" xyz="0 0.035 0.11683"/>
    <axis xyz="1 0 0"/>
    <parent link="H0_F0_base_link"/>
    <child link="H0_F0_link_1"/>
    <limit effort="2" lower="-1.3962634" upper="1.04719755" velocity="1.0"/>
    <dynamics damping="0.1"/>
  </joint>
  <joint name="H0_F0J2" type="revolute">
    <origin rpy="-0.0068649 1.7347E-18 1.6176E-16" xyz="0 0 0.06"/>
    <axis xyz="1 0 0"/>
    <parent link="H0_F0_link_1"/>
    <child link="H0_F0_link_2"/>
    <limit effort="2" lower="-1.04719755" upper="1.3962634" velocity="1.0"/>
    <dynamics damping="0.01"/>
  </joint>
  <transmission name="H0_F0J0_transmission">
    <type>transmission_interface/SimpleTransmission</type>
    <actuator name="H0_F0J0">
      <mechanicalReduction>1</mechanicalReduction>
    </actuator>
    <joint name="H0_F0J0">
      <hardwareInterface>EffortJointInterface</hardwareInterface>
    </joint>
  </transmission>
  <transmission name="H0_F0J1_transmission">
    <type>transmission_interface/SimpleTransmission</type>
    <actuator name="H0_F0J1">
      <mechanicalReduction>1</mechanicalReduction>
    </actuator>
    <joint name="H0_F0J1">
      <hardwareInterface>EffortJointInterface</hardwareInterface>
    </joint>
  </transmission>
  <transmission name="H0_F0J2_transmission">
    <type>transmission_interface/SimpleTransmission</type>
    <actuator name="H0_F0J2">
      <mechanicalReduction>1</mechanicalReduction>
    </actuator>
    <joint name="H0_F0J2">
      <hardwareInterface>EffortJointInterface</hardwareInterface>
    </joint>
  </transmission>
  <link name="H0_F0_tip"/>
  <link name="H0_F0_optoforce"/>
  <joint name="H0_F0_tip_to_optoforce" type="fixed">
    <parent link="H0_F0_tip"/>
    <child link="H0_F0_optoforce"/>
    <origin rpy="-0.35 0 0" xyz="0 -0.006 0.046"/>
  </joint>
  <joint name="H0_F0_tip" type="fixed">
    <parent link="H0_F0_link_2"/>
    <child link="H0_F0_tip"/>
  </joint>
  <link name="H0_F1_palm_link">
    <inertial>
      <origin rpy="0 0 0" xyz="-0.00681802120880393 -0.00947020456878004 0.067587996682422"/>
      <mass value="0.095"/>
      <inertia ixx="2.79747833772125E-05" ixy="-5.50900644725373E-08" ixz="-2.82072424927723E-07" iyy="2.67800858812928E-05" iyz="3.1953125069394E-06" izz="9.86122271726361E-06"/>
    </inertial>
    <visual>
      <origin rpy="0 0 0" xyz="0 0 0"/>
      <geometry>
        <mesh filename="package://fh_description/meshes/v2/finger_palm_link.stl"/>
      </geometry>
      <material name="dark_grey">
        <color rgba="0.267 0.267 0.267 1.0"/>
      </material>
    </visual>
    <!-- Collision mesh no needed as it is part of palm_link_col.stl collision mesh -->
    <!--xacro:mesh_collision file_name="v2/finger_palm_link.stl">
        <origin xyz="0 0 0" rpy="0 0 0" />
        <xacro:dark_grey/>
      </xacro:mesh_collision-->
  </link>
  <gazebo reference="H0_F1_palm_link">
    <material>Gazebo/DarkGrey</material>
  </gazebo>
  <link name="H0_F1_base_link">
    <inertial>
      <origin rpy="0 0 0" xyz="-0.00027 0.02711 0.06013"/>
      <mass value="0.416"/>
      <inertia ixx="0.00226490263" ixy="3.77717E-06" ixz="5.80703E-06" iyy="0.00193941498" iyz="6.9931504E-04" izz="0.00053136647"/>
    </inertial>
    <visual>
      <origin rpy="0 0 0" xyz="0 0 0"/>
      <geometry>
        <mesh filename="package://fh_description/meshes/v2/finger_base_link.stl"/>
      </geometry>
      <material name="dark_grey">
        <color rgba="0.267 0.267 0.267 1.0"/>
      </material>
    </visual>
    <collision>
      <origin rpy="0 0 0" xyz="0 0 0"/>
      <geometry>
        <mesh filename="package://fh_description/meshes/v2/finger_base_link_col.stl"/>
      </geometry>
      <material name="dark_grey">
        <color rgba="0.267 0.267 0.267 1.0"/>
      </material>
    </collision>
  </link>
  <gazebo reference="H0_F1_base_link">
    <material>Gazebo/DarkGrey</material>
  </gazebo>
  <link name="H0_F1_link_1">
    <inertial>
      <origin rpy="0 0 0" xyz="-0.00071 -0.00022 0.01415"/>
      <mass value="0.254"/>
      <inertia ixx="0.00019133634" ixy="-0.00000008786" ixz="-0.00000720119" iyy="0.00021397597" iyz="-0.00000201648" izz="0.00008396436"/>
    </inertial>
    <visual>
      <origin rpy="0 0 0" xyz="0 0 0"/>
      <geometry>
        <mesh filename="package://fh_description/meshes/v2/finger_prox_link.stl"/>
      </geometry>
      <material name="dark_grey">
        <color rgba="0.267 0.267 0.267 1.0"/>
      </material>
    </visual>
    <collision>
      <origin rpy="0 0 0" xyz="0 0 0"/>
      <geometry>
        <mesh filename="package://fh_description/meshes/v2/finger_prox_link_col.stl"/>
      </geometry>
      <material name="dark_grey">
        <color rgba="0.267 0.267 0.267 1.0"/>
      </material>
    </collision>
  </link>
  <gazebo reference="H0_F1_link_1">
    <material>Gazebo/DarkGrey</material>
  </gazebo>
  <link name="H0_F1_link_2">
    <inertial>
      <origin rpy="0 0 0" xyz="0.00197 -0.00166 0.00962"/>
      <mass value="0.071"/>
      <inertia ixx="0.0000351756" ixy="0.0000000072" ixz="0.00000014613" iyy="0.00003639824" iyz="-0.00000538058" izz="0.00001224172"/>
    </inertial>
    <visual>
      <origin rpy="0 0 0" xyz="0 0 0"/>
      <geometry>
        <mesh filename="package://fh_description/meshes/v2/finger_dist_link.stl"/>
      </geometry>
      <material name="dark_grey">
        <color rgba="0.267 0.267 0.267 1.0"/>
      </material>
    </visual>
    <collision>
      <origin rpy="0 0 0" xyz="0 0 0"/>
      <geometry>
        <mesh filename="package://fh_description/meshes/v2/finger_dist_link.stl"/>
      </geometry>
      <material name="dark_grey">
        <color rgba="0.267 0.267 0.267 1.0"/>
      </material>
    </collision>
  </link>
  <gazebo reference="H0_F1_link_2">
    <material>Gazebo/DarkGrey</material>
  </gazebo>
  <joint name="H0_F1Palm" type="fixed">
    <origin rpy="0 0 0" xyz="0 0 0"/>
    <parent link="H0_insert_F1"/>
    <child link="H0_F1_palm_link"/>
  </joint>
  <joint name="H0_F1J0" type="revolute">
    <origin rpy="-8.8818E-16 -1.0061E-16 0.022402" xyz="0 0 0.00016528"/>
    <axis xyz="0 0 1"/>
    <parent link="H0_F1_palm_link"/>
    <child link="H0_F1_base_link"/>
    <limit effort="2" lower="-0.7853981625" upper="0.7853981625" velocity="1.0"/>
    <dynamics damping="0.01"/>
  </joint>
  <joint name="H0_F1J1" type="revolute">
    <origin rpy="0.070695 6.9389E-16 2.0947E-16" xyz="0 0.035 0.11683"/>
    <axis xyz="1 0 0"/>
    <parent link="H0_F1_base_link"/>
    <child link="H0_F1_link_1"/>
    <limit effort="2" lower="-1.3962634" upper="1.04719755" velocity="1.0"/>
    <dynamics damping="0.1"/>
  </joint>
  <joint name="H0_F1J2" type="revolute">
    <origin rpy="-0.0068649 1.7347E-18 1.6176E-16" xyz="0 0 0.06"/>
    <axis xyz="1 0 0"/>
    <parent link="H0_F1_link_1"/>
    <child link="H0_F1_link_2"/>
    <limit effort="2" lower="-1.04719755" upper="1.3962634" velocity="1.0"/>
    <dynamics damping="0.01"/>
  </joint>
  <transmission name="H0_F1J0_transmission">
    <type>transmission_interface/SimpleTransmission</type>
    <actuator name="H0_F1J0">
      <mechanicalReduction>1</mechanicalReduction>
    </actuator>
    <joint name="H0_F1J0">
      <hardwareInterface>EffortJointInterface</hardwareInterface>
    </joint>
  </transmission>
  <transmission name="H0_F1J1_transmission">
    <type>transmission_interface/SimpleTransmission</type>
    <actuator name="H0_F1J1">
      <mechanicalReduction>1</mechanicalReduction>
    </actuator>
    <joint name="H0_F1J1">
      <hardwareInterface>EffortJointInterface</hardwareInterface>
    </joint>
  </transmission>
  <transmission name="H0_F1J2_transmission">
    <type>transmission_interface/SimpleTransmission</type>
    <actuator name="H0_F1J2">
      <mechanicalReduction>1</mechanicalReduction>
    </actuator>
    <joint name="H0_F1J2">
      <hardwareInterface>EffortJointInterface</hardwareInterface>
    </joint>
  </transmission>
  <link name="H0_F1_tip"/>
  <link name="H0_F1_optoforce"/>
  <joint name="H0_F1_tip_to_optoforce" type="fixed">
    <parent link="H0_F1_tip"/>
    <child link="H0_F1_optoforce"/>
    <origin rpy="-0.35 0 0" xyz="0 -0.006 0.046"/>
  </joint>
  <joint name="H0_F1_tip" type="fixed">
    <parent link="H0_F1_link_2"/>
    <child link="H0_F1_tip"/>
  </joint>
  <link name="H0_F2_palm_link">
    <inertial>
      <origin rpy="0 0 0" xyz="-0.00681802120880393 -0.00947020456878004 0.067587996682422"/>
      <mass value="0.095"/>
      <inertia ixx="2.79747833772125E-05" ixy="-5.50900644725373E-08" ixz="-2.82072424927723E-07" iyy="2.67800858812928E-05" iyz="3.1953125069394E-06" izz="9.86122271726361E-06"/>
    </inertial>
    <visual>
      <origin rpy="0 0 0" xyz="0 0 0"/>
      <geometry>
        <mesh filename="package://fh_description/meshes/v2/finger_palm_link.stl"/>
      </geometry>
      <material name="dark_grey">
        <color rgba="0.267 0.267 0.267 1.0"/>
      </material>
    </visual>
    <!-- Collision mesh no needed as it is part of palm_link_col.stl collision mesh -->
    <!--xacro:mesh_collision file_name="v2/finger_palm_link.stl">
        <origin xyz="0 0 0" rpy="0 0 0" />
        <xacro:dark_grey/>
      </xacro:mesh_collision-->
  </link>
  <gazebo reference="H0_F2_palm_link">
    <material>Gazebo/DarkGrey</material>
  </gazebo>
  <link name="H0_F2_base_link">
    <inertial>
      <origin rpy="0 0 0" xyz="-0.00027 0.02711 0.06013"/>
      <mass value="0.416"/>
      <inertia ixx="0.00226490263" ixy="3.77717E-06" ixz="5.80703E-06" iyy="0.00193941498" iyz="6.9931504E-04" izz="0.00053136647"/>
    </inertial>
    <visual>
      <origin rpy="0 0 0" xyz="0 0 0"/>
      <geometry>
        <mesh filename="package://fh_description/meshes/v2/finger_base_link.stl"/>
      </geometry>
      <material name="dark_grey">
        <color rgba="0.267 0.267 0.267 1.0"/>
      </material>
    </visual>
    <collision>
      <origin rpy="0 0 0" xyz="0 0 0"/>
      <geometry>
        <mesh filename="package://fh_description/meshes/v2/finger_base_link_col.stl"/>
      </geometry>
      <material name="dark_grey">
        <color rgba="0.267 0.267 0.267 1.0"/>
      </material>
    </collision>
  </link>
  <gazebo reference="H0_F2_base_link">
    <material>Gazebo/DarkGrey</material>
  </gazebo>
  <link name="H0_F2_link_1">
    <inertial>
      <origin rpy="0 0 0" xyz="-0.00071 -0.00022 0.01415"/>
      <mass value="0.254"/>
      <inertia ixx="0.00019133634" ixy="-0.00000008786" ixz="-0.00000720119" iyy="0.00021397597" iyz="-0.00000201648" izz="0.00008396436"/>
    </inertial>
    <visual>
      <origin rpy="0 0 0" xyz="0 0 0"/>
      <geometry>
        <mesh filename="package://fh_description/meshes/v2/finger_prox_link.stl"/>
      </geometry>
      <material name="dark_grey">
        <color rgba="0.267 0.267 0.267 1.0"/>
      </material>
    </visual>
    <collision>
      <origin rpy="0 0 0" xyz="0 0 0"/>
      <geometry>
        <mesh filename="package://fh_description/meshes/v2/finger_prox_link_col.stl"/>
      </geometry>
      <material name="dark_grey">
        <color rgba="0.267 0.267 0.267 1.0"/>
      </material>
    </collision>
  </link>
  <gazebo reference="H0_F2_link_1">
    <material>Gazebo/DarkGrey</material>
  </gazebo>
  <link name="H0_F2_link_2">
    <inertial>
      <origin rpy="0 0 0" xyz="0.00197 -0.00166 0.00962"/>
      <mass value="0.071"/>
      <inertia ixx="0.0000351756" ixy="0.0000000072" ixz="0.00000014613" iyy="0.00003639824" iyz="-0.00000538058" izz="0.00001224172"/>
    </inertial>
    <visual>
      <origin rpy="0 0 0" xyz="0 0 0"/>
      <geometry>
        <mesh filename="package://fh_description/meshes/v2/finger_dist_link.stl"/>
      </geometry>
      <material name="dark_grey">
        <color rgba="0.267 0.267 0.267 1.0"/>
      </material>
    </visual>
    <collision>
      <origin rpy="0 0 0" xyz="0 0 0"/>
      <geometry>
        <mesh filename="package://fh_description/meshes/v2/finger_dist_link.stl"/>
      </geometry>
      <material name="dark_grey">
        <color rgba="0.267 0.267 0.267 1.0"/>
      </material>
    </collision>
  </link>
  <gazebo reference="H0_F2_link_2">
    <material>Gazebo/DarkGrey</material>
  </gazebo>
  <joint name="H0_F2Palm" type="fixed">
    <origin rpy="0 0 0" xyz="0 0 0"/>
    <parent link="H0_insert_F2"/>
    <child link="H0_F2_palm_link"/>
  </joint>
  <joint name="H0_F2J0" type="revolute">
    <origin rpy="-8.8818E-16 -1.0061E-16 0.022402" xyz="0 0 0.00016528"/>
    <axis xyz="0 0 1"/>
    <parent link="H0_F2_palm_link"/>
    <child link="H0_F2_base_link"/>
    <limit effort="2" lower="-0.7853981625" upper="0.7853981625" velocity="1.0"/>
    <dynamics damping="0.01"/>
  </joint>
  <joint name="H0_F2J1" type="revolute">
    <origin rpy="0.070695 6.9389E-16 2.0947E-16" xyz="0 0.035 0.11683"/>
    <axis xyz="1 0 0"/>
    <parent link="H0_F2_base_link"/>
    <child link="H0_F2_link_1"/>
    <limit effort="2" lower="-1.3962634" upper="1.04719755" velocity="1.0"/>
    <dynamics damping="0.1"/>
  </joint>
  <joint name="H0_F2J2" type="revolute">
    <origin rpy="-0.0068649 1.7347E-18 1.6176E-16" xyz="0 0 0.06"/>
    <axis xyz="1 0 0"/>
    <parent link="H0_F2_link_1"/>
    <child link="H0_F2_link_2"/>
    <limit effort="2" lower="-1.04719755" upper="1.3962634" velocity="1.0"/>
    <dynamics damping="0.01"/>
  </joint>
  <transmission name="H0_F2J0_transmission">
    <type>transmission_interface/SimpleTransmission</type>
    <actuator name="H0_F2J0">
      <mechanicalReduction>1</mechanicalReduction>
    </actuator>
    <joint name="H0_F2J0">
      <hardwareInterface>EffortJointInterface</hardwareInterface>
    </joint>
  </transmission>
  <transmission name="H0_F2J1_transmission">
    <type>transmission_interface/SimpleTransmission</type>
    <actuator name="H0_F2J1">
      <mechanicalReduction>1</mechanicalReduction>
    </actuator>
    <joint name="H0_F2J1">
      <hardwareInterface>EffortJointInterface</hardwareInterface>
    </joint>
  </transmission>
  <transmission name="H0_F2J2_transmission">
    <type>transmission_interface/SimpleTransmission</type>
    <actuator name="H0_F2J2">
      <mechanicalReduction>1</mechanicalReduction>
    </actuator>
    <joint name="H0_F2J2">
      <hardwareInterface>EffortJointInterface</hardwareInterface>
    </joint>
  </transmission>
  <link name="H0_F2_tip"/>
  <link name="H0_F2_optoforce"/>
  <joint name="H0_F2_tip_to_optoforce" type="fixed">
    <parent link="H0_F2_tip"/>
    <child link="H0_F2_optoforce"/>
    <origin rpy="-0.35 0 0" xyz="0 -0.006 0.046"/>
  </joint>
  <joint name="H0_F2_tip" type="fixed">
    <parent link="H0_F2_link_2"/>
    <child link="H0_F2_tip"/>
  </joint>
  <link name="H0_mounting_plate">
    <inertial>
      <origin rpy="0 0 0" xyz="0.00001 -0.00205 0.00473"/>
      <mass value="0.02442"/>
      <inertia ixx="9.30752E-06" ixy="4.58E-09" ixz="1.46E-09" iyy="1.060685E-05" iyz="-5.4393E-07" izz="1.840588E-05"/>
    </inertial>
    <visual>
      <origin rpy="0 0 0" xyz="0 0 0"/>
      <geometry>
        <mesh filename="package://fh_description/meshes/v2/mount_link_50_4_M6.stl"/>
      </geometry>
      <material name="dark_grey">
        <color rgba="0.267 0.267 0.267 1.0"/>
      </material>
    </visual>
    <collision>
      <origin rpy="0 0 0" xyz="0 0 0"/>
      <geometry>
        <mesh filename="package://fh_description/meshes/v2/mount_link_50_4_M6_col.stl"/>
      </geometry>
      <material name="dark_grey">
        <color rgba="0.267 0.267 0.267 1.0"/>
      </material>
    </collision>
  </link>
  <gazebo reference="H0_mounting_plate">
    <material>Gazebo/DarkGrey</material>
  </gazebo>
  <joint name="H0_mounting_plate_to_hand" type="fixed">
    <parent link="H0_mounting_plate"/>
    <child link="H0_base_attach"/>
    <origin rpy="0 0 0" xyz="0 0.0 0.01"/>
  </joint>
  <joint name="ra_arm_to_mounting_plate" type="fixed">
    <parent link="ra_ee_link"/>
    <child link="H0_mounting_plate"/>
    <origin rpy="1.570796325 3.14159265 1.570796325" xyz="0.0 0.0 0.0"/>
  </joint>
</robot>

